Workbook

Sheet BOM RAW
A1: Parent Item | B1: Component Item | C1: Level | D1: Quantity Per Assembly | E1: Unit
A2: FG-100 | B2: PK-301 | C2: 1 | D2: 1 | E2: Box
A3: FG-100 | B3: RM-201 | C3: 1 | D3: 2 | E3: Pcs
A4: FG-100 | B4: RM-202 | C4: 1 | D4: 1 | E4: Pcs
A5: FG-100 | B5: SA-110 | C5: 1 | D5: 1 | E5: Set
A6: FG-200 | B6: PK-302 | C6: 1 | D6: 1 | E6: Box
A7: FG-200 | B7: RM-206 | C7: 1 | D7: 4 | E7: Pcs
A8: FG-200 | B8: RM-207 | C8: 1 | D8: 2 | E8: Pcs
A9: FG-200 | B9: SA-210 | C9: 1 | D9: 1 | E9: Set
A10: FG-300 | B10: PK-303 | C10: 1 | D10: 1 | E10: Box
A11: FG-300 | B11: RM-211 | C11: 1 | D11: 2 | E11: Pcs
A12: FG-300 | B12: RM-212 | C12: 1 | D12: 2 | E12: Pcs
A13: FG-300 | B13: SA-310 | C13: 1 | D13: 1 | E13: Set
... A22: SA-310 | B22: RM-215 | C22: 2 | D22: 1 | E22: Pcs

Sheet Struktur BOM

Sheet ITEM MASTER
A1: Item Code | B1: Item Name | C1: Item Type | D1: On Hand Inventory | E1: Safety Stock | F1: Lot Sizing Rule | G1: Lot Size | H1: Lead Time | I1: Unit
A2: FG-100 | B2: Smart Blender 1L | C2: Finished Goods | D2: 120 | E2: 50 | F2: Fixed Lot Size | G2: 100 | H2: 1 | I2: Unit
A3: FG-200 | B3: Digital Rice Cooker | C3: Finished Goods | D3: 95 | E3: 40 | F3: Fixed Lot Size | G3: 100 | H3: 1 | I3: Unit
A4: FG-300 | B4: Air Fryer Compact | C4: Finished Goods | D4: 150 | E4: 35 | F4: Fixed Lot Size | G4: 80 | H4: 1 | I4: Unit
A5: PK-301 | B5: Retail Box Blender | C5: Packaging | D5: 150 | E5: 50 | F5: Fixed Lot Size | G5: 200 | H5: 1 | I5: Box
A6: PK-302 | B6: Retail Box Rice Cooker | C6: Packaging | D6: 110 | E6: 40 | F6: Fixed Lot Size | G6: 200 | H6: 1 | I6: Box
A7: PK-303 | B7: Retail Box Air Fryer | C7: Packaging | D7: 85 | E7: 30 | F7: Fixed lot | G7: 150 | H7: 1 | I7: Box
A8: RM-201 | B8: Plastic Housing | C8: Raw Material | D8: 300 | E8: 100 | F8: Lot-for-Lot | G8: 0 | H8: 1 | I8: Pcs
A9: RM-202 | B9: Control Knob | C9: Raw Material | D9: 240 | E9: 80 | F9: L4L | G9: 0 | H9: 1 | I9: Pcs
A10: RM-203 | B10: Copper Wire | C10: Raw Material | D10: 650 | E10: 200 | F10: Fixed Lot Size | G10: 500 | H10: 2 | I10: Meter
A11: RM-204 | B11: Screw M4 | C11: Raw Material | D11: 900 | E11: 300 | F11: Fixed Lot Size | G11: 1000 | H11: 1 | I11: Pcs
A12: RM-205 | B12: Motor Bearing | C12: Raw Material | D12: 180 | E12: 60 | F12: Lot for Lot | G12: 0 | H12: 2 | I12: Pcs
A13: RM-206 | B13: Outer Casing | C13: Raw Material | D13: 260 | E13: 100 | F13: Lot-for-Lot | G13: 0 | H13: 1 | I13: Pcs
... A25: SA-310 | B25: Fan Heater Assembly | C25: Sub Assembly | D25: 55 | E25: 20 | F25: Fixed Lot Size | G25: 60 | H25: 1 | I25: Set

Sheet MPS INPUT
A1: Product Code | B1: Week | C1: MPS Quantity
A2: FG-100 | B2: Week 1 | C2: 80
A3: FG-100 | B3: Week 2 | C3: 120
A4: FG-100 | B4: Week 3 | C4: 100
A5: FG-100 | B5: Week 4 | C5: 140
A6: FG-100 | B6: Week 5 | C6: 160
A7: FG-100 | B7: Week 6 | C7: 130
A8: FG-100 | B8: Week 7 | C8: 170
A9: FG-100 | B9: Week 8 | C9: 150
A10: FG-200 | B10: Week 1 | C10: 70
A11: FG-200 | B11: Week 2 | C11: 90
A12: FG-200 | B12: Week 3 | C12: 110
A13: FG-200 | B13: Week 4 | C13: 120
... A25: FG-300 | B25: Week 8 | C25: 130

Sheet MRP
A1: MRP
A2: Item FG-100 | C2: Item Code | D2: FG-100 | E2: =(_xlfn.XMATCH(D2,Item[Item Code],0,))+1 -> 2 | M2: Item FG-200 | O2: Item Code | P2: FG-200 | Q2: =(_xlfn.XMATCH(P2,Item[Item Code],0,))+1 -> 3 | Y2: Item FG-300 | AA2: Item Code | AB2: FG-300 | AC2: =(_xlfn.XMATCH(AB2,Item[Item Code],0,))+1 -> 4 | AK2: Item SA-110 | AM2: Item Code | AN2: SA-110 | AO2: 23 | AW2: Item SA-210 | AY2: Item Code | AZ2: SA-210 | BA2: 24 | BI2: Item SA-310 | BK2: Item Code | BL2: SA-310 | BM2: 25
C3: On Hand Inventory | D3: =HLOOKUP(C3,Item[[#All],[Item Code]:[Lead Time]],E$2,) -> 120 | O3: On Hand Inventory | P3: =HLOOKUP(O3,Item[[#All],[Item Code]:[Lead Time]],Q$2,) -> 95 | AA3: On Hand Inventory | AB3: =HLOOKUP(AA3,Item[[#All],[Item Code]:[Lead Time]],AC$2,) -> 150 | AM3: On Hand Inventory | AN3: 80 | AY3: On Hand Inventory | AZ3: 70 | BK3: On Hand Inventory | BL3: 55
C4: Safety Stock | D4: =HLOOKUP(C4,Item[[#All],[Item Code]:[Lead Time]],E$2,) -> 50 | O4: Safety Stock | P4: =HLOOKUP(O4,Item[[#All],[Item Code]:[Lead Time]],Q$2,) -> 40 | AA4: Safety Stock | AB4: =HLOOKUP(AA4,Item[[#All],[Item Code]:[Lead Time]],AC$2,) -> 35 | AM4: Safety Stock | AN4: 30 | AY4: Safety Stock | AZ4: 25 | BK4: Safety Stock | BL4: 20
C5: Lot Size | D5: =HLOOKUP(C5,Item[[#All],[Item Code]:[Lead Time]],E$2,) -> 100 | O5: Lot Size | P5: =HLOOKUP(O5,Item[[#All],[Item Code]:[Lead Time]],Q$2,) -> 100 | AA5: Lot Size | AB5: =HLOOKUP(AA5,Item[[#All],[Item Code]:[Lead Time]],AC$2,) -> 80 | AM5: Lot Size | AN5: 80 | AY5: Lot Size | AZ5: 60 | BK5: Lot Size | BL5: 60
C6: Lead Time | D6: =HLOOKUP(C6,Item[[#All],[Item Code]:[Lead Time]],E$2,) -> 1 | O6: Lead Time | P6: =HLOOKUP(O6,Item[[#All],[Item Code]:[Lead Time]],Q$2,) -> 1 | AA6: Lead Time | AB6: =HLOOKUP(AA6,Item[[#All],[Item Code]:[Lead Time]],AC$2,) -> 1 | AM6: Lead Time | AN6: 1 | AY6: Lead Time | AZ6: 1 | BK6: Lead Time | BL6: 1
C7: Jumlah | D7: =_xlfn.XLOOKUP(D2,BOM[Parent Item],BOM[Quantity Per Assembly]) -> 1 | O7: Jumlah | P7: =_xlfn.XLOOKUP(P2,BOM[Parent Item],BOM[Quantity Per Assembly]) -> 1 | AA7: Jumlah | AB7: =_xlfn.XLOOKUP(AB2,BOM[Parent Item],BOM[Quantity Per Assembly]) -> 1 | AM7: Jumlah | AN7: 1 | AY7: Jumlah | AZ7: 1 | BK7: Jumlah | BL7: 1
C8: Minggu | D8: {=_xlfn.SEQUENCE(,9,0)} -> 0 | E8: 1 | F8: 2 | G8: 3 | H8: 4 | I8: 5 | J8: 6 | K8: 7 | L8: 8 | O8: Minggu | P8: {=_xlfn.SEQUENCE(,9,0)} -> 0 | Q8: 1 | R8: 2 | S8: 3 | T8: 4 | U8: 5 | V8: 6 | W8: 7 | X8: 8 | AA8: Minggu | AB8: {=_xlfn.SEQUENCE(,9,0)} -> 0 | AC8: 1 | AD8: 2 | AE8: 3 | AF8: 4 | AG8: 5 | AH8: 6 | AI8: 7 | AJ8: 8 | AM8: Minggu | AN8: 0 | AO8: 1 | AP8: 2 | AQ8: 3 | AR8: 4 | AS8: 5 | AT8: 6 | AU8: 7 | AV8: 8 | AY8: Minggu | AZ8: 0 | BA8: 1 | BB8: 2 | BC8: 3 | BD8: 4 | BE8: 5 | BF8: 6 | BG8: 7 | BH8: 8 | BK8: Minggu | BL8: 0 | BM8: 1 | BN8: 2 | BO8: 3 | BP8: 4 | BQ8: 5 | BR8: 6 | BS8: 7 | BT8: 8
C9: Gross Requirement | E9: {=TRANSPOSE('MPS INPUT'!C2:C9)} -> 80 | F9: 120 | G9: 100 | H9: 140 | I9: 160 | J9: 130 | K9: 170 | L9: 150 | O9: Gross Requirement | Q9: {=TRANSPOSE('MPS INPUT'!C10:C17)} -> 70 | R9: 90 | S9: 110 | T9: 120 | U9: 130 | V9: 120 | W9: 150 | X9: 140 | AA9: Gross Requirement | AC9: {=TRANSPOSE('MPS INPUT'!C18:C25)} -> 60 | AD9: 80 | AE9: 95 | AF9: 100 | AG9: 105 | AH9: 110 | AI9: 125 | AJ9: 130 | AM9: Gross Requirement | AN9: 0 | AO9: 0 | AP9: 100 | AQ9: 100 | AR9: 100 | AS9: 100 | AT9: 200 | AU9: 0 | AV9: 0 | AY9: Gross Requirement | BA9: 0 | BB9: 100 | BC9: 100 | BD9: 100 | BE9: 100 | BF9: 200 | BG9: 100 | BH9: 0 | BK9: Gross Requirement | BM9: 0 | BN9: 80 | BO9: 80 | BP9: 160 | BQ9: 80 | BR9: 160 | BS9: 80 | BT9: 0
C10: Scheduled Receipt | E10: {=TRANSPOSE('SCHEDULE RECEIPT'!C2:C9)} -> 0 | F10: 100 | G10: 0 | H10: 0 | I10: 100 | J10: 0 | K10: 0 | L10: 100 | O10: Scheduled Receipt | R10: 100 | AA10: Scheduled Receipt | AD10: 80 | AM10: Scheduled Receipt | AP10: 80 | AS10: 80 | AY10: Scheduled Receipt | BC10: 60 | BK10: Scheduled Receipt | BO10: 60
C11: On Hand | D11: =D3 -> 120 | E11: =D11+E13+E10+-E9 -> 140 | F11: =E11+F13+F10+-F9 -> 120 | G11: =F11+G13+G10+-G9 -> 120 | H11: =G11+H13+H10+-H9 -> 80 | I11: =H11+I13+I10+-I9 -> 120 | J11: =I11+J13+J10+-J9 -> 90 | K11: =J11+K13+K10+-K9 -> 120 | L11: =K11+L13+L10+-L9 -> 70 | O11: On Hand | P11: =P3 -> 95 | Q11: =P11+Q13+Q10+-Q9 -> 125 | R11: =Q11+R13+R10+-R9 -> 135 | S11: =R11+S13+S10+-S9 -> 125 | T11: =S11+T13+T10+-T9 -> 105 | U11: =T11+U13+U10+-U9 -> 75 | V11: =U11+V13+V10+-V9 -> 55 | W11: =V11+W13+W10+-W9 -> 105 | X11: =W11+X13+X10+-X9 -> 65 | AA11: On Hand | AB11: =AB3 -> 150 | AC11: =AB11+AC13+AC10+-AC9 -> 90 | AD11: =AC11+AD13+AD10+-AD9 -> 90 | AE11: =AD11+AE13+AE10+-AE9 -> 75 | AF11: =AE11+AF13+AF10+-AF9 -> 55 | AG11: =AF11+AG13+AG10+-AG9 -> 110 | AH11: =AG11+AH13+AH10+-AH9 -> 80 | AI11: =AH11+AI13+AI10+-AI9 -> 115 | AJ11: =AI11+AJ13+AJ10+-AJ9 -> 65 | AM11: On Hand | AN11: 80 | AO11: 80 | AP11: 60 | AQ11: 40 | AR11: 100 | AS11: 80 | AT11: 40 | AU11: 40 | AV11: 40 | AY11: On Hand | AZ11: 70 | BA11: 70 | BB11: 30 | BC11: 50 | BD11: 70 | BE11: 30 | BF11: 70 | BG11: 30 | BH11: 30 | BK11: On Hand | BL11: 55 | BM11: 55 | BN11: 35 | BO11: 75 | BP11: 35 | BQ11: 75 | BR11: 35 | BS11: 75 | BT11: 75
C12: Net Requirement | E12: =IF(E9+$D$4-E10-D11<0, 0,E9+$D$4-E10-D11) -> 10 | F12: =IF(F9+$D$4-F10-E11<0, 0,F9+$D$4-F10-E11) -> 0 | G12: =IF(G9+$D$4-G10-F11<0, 0,G9+$D$4-G10-F11) -> 30 | H12: =IF(H9+$D$4-H10-G11<0, 0,H9+$D$4-H10-G11) -> 70 | I12: =IF(I9+$D$4-I10-H11<0, 0,I9+$D$4-I10-H11) -> 30 | J12: =IF(J9+$D$4-J10-I11<0, 0,J9+$D$4-J10-I11) -> 60 | K12: =IF(K9+$D$4-K10-J11<0, 0,K9+$D$4-K10-J11) -> 130 | L12: =IF(L9+$D$4-L10-K11<0, 0,L9+$D$4-L10-K11) -> 0 | O12: Net Requirement | Q12: =IF(Q9+$P$4-Q10-P11<0, 0,Q9+$P$4-Q10-P11) -> 15 | R12: =IF(R9+$P$4-R10-Q11<0, 0,R9+$P$4-R10-Q11) -> 0 | S12: =IF(S9+$P$4-S10-R11<0, 0,S9+$P$4-S10-R11) -> 15 | T12: =IF(T9+$P$4-T10-S11<0, 0,T9+$P$4-T10-S11) -> 35 | U12: =IF(U9+$P$4-U10-T11<0, 0,U9+$P$4-U10-T11) -> 65 | V12: =IF(V9+$P$4-V10-U11<0, 0,V9+$P$4-V10-U11) -> 85 | W12: =IF(W9+$P$4-W10-V11<0, 0,W9+$P$4-W10-V11) -> 135 | X12: =IF(X9+$P$4-X10-W11<0, 0,X9+$P$4-X10-W11) -> 75 | AA12: Net Requirement | AC12: =IF(AC9+$AB$4-AC10-AB11<0, 0,AC9+$AB$4-AC10-AB11) -> 0 | AD12: =IF(AD9+$P$4-AD10-AC11<0, 0,AD9+$P$4-AD10-AC11) -> 0 | AE12: =IF(AE9+$P$4-AE10-AD11<0, 0,AE9+$P$4-AE10-AD11) -> 45 | AF12: =IF(AF9+$P$4-AF10-AE11<0, 0,AF9+$P$4-AF10-AE11) -> 65 | AG12: =IF(AG9+$P$4-AG10-AF11<0, 0,AG9+$P$4-AG10-AF11) -> 90 | AH12: =IF(AH9+$P$4-AH10-AG11<0, 0,AH9+$P$4-AH10-AG11) -> 40 | AI12: =IF(AI9+$P$4-AI10-AH11<0, 0,AI9+$P$4-AI10-AH11) -> 85 | AJ12: =IF(AJ9+$P$4-AJ10-AI11<0, 0,AJ9+$P$4-AJ10-AI11) -> 55 | AM12: Net Requirement | AO12: 0 | AP12: 0 | AQ12: 70 | AR12: 90 | AS12: 0 | AT12: 150 | AU12: 0 | AV12: 0 | AY12: Net Requirement | BA12: 0 | BB12: 55 | BC12: 35 | BD12: 75 | BE12: 55 | BF12: 195 | BG12: 55 | BH12: 0 | BK12: Net Requirement | BM12: 0 | BN12: 45 | BO12: 5 | BP12: 105 | BQ12: 65 | BR12: 105 | BS12: 65 | BT12: 0
C13: Planned Production Order | E13: =D14 -> 100 | F13: =E14 -> 0 | G13: =F14 -> 100 | H13: =G14 -> 100 | I13: =H14 -> 100 | J13: =I14 -> 100 | K13: =J14 -> 200 | L13: =K14 -> 0 | O13: Planned Production Order | Q13: =P14 -> 100 | R13: =Q14 -> 0 | S13: =R14 -> 100 | T13: =S14 -> 100 | U13: =T14 -> 100 | V13: =U14 -> 100 | W13: =V14 -> 200 | X13: =W14 -> 100 | AA13: Planned Production Order | AC13: =AB14 -> 0 | AD13: =AC14 -> 0 | AE13: =AD14 -> 80 | AF13: =AE14 -> 80 | AG13: =AF14 -> 160 | AH13: =AG14 -> 80 | AI13: =AH14 -> 160 | AJ13: =AI14 -> 80 | AM13: Planned Production Order | AO13: 0 | AP13: 0 | AQ13: 80 | AR13: 160 | AS13: 0 | AT13: 160 | AU13: 0 | AV13: 0 | AY13: Planned Production Order | BA13: 0 | BB13: 60 | BC13: 60 | BD13: 120 | BE13: 60 | BF13: 240 | BG13: 60 | BH13: 0 | BK13: Planned Production Order | BM13: 0 | BN13: 60 | BO13: 60 | BP13: 120 | BQ13: 120 | BR13: 120 | BS13: 120 | BT13: 0
C14: Planned Production Release | D14: 100 | F14: 100 | G14: 100 | H14: 100 | I14: 100 | J14: 200 | O14: Planned Production Release | P14: 100 | R14: 100 | S14: 100 | T14: 100 | U14: 100 | V14: 200 | W14: 100 | AA14: Planned Production Release | AD14: 80 | AE14: 80 | AF14: 160 | AG14: 80 | AH14: 160 | AI14: 80 | AM14: Planned Production Release | AP14: 80 | AQ14: 160 | AS14: 160 | AY14: Planned Production Release | BA14: 60 | BB14: 60 | BC14: 120 | BD14: 60 | BE14: 240 | BF14: 60 | BK14: Planned Production Release | BM14: 60 | BN14: 60 | BO14: 120 | BP14: 120 | BQ14: 120 | BR14: 120
C17: Item Code | D17: RM-201 | E17: =(_xlfn.XMATCH(D17,Item[Item Code],0,))+1 -> 8 | O17: Item Code | P17: PK-302 | Q17: =(_xlfn.XMATCH(P17,Item[Item Code],0,))+1 -> 6 | AA17: Item Code | AB17: PK-303 | AC17: =(_xlfn.XMATCH(AB17,Item[Item Code],0,))+1 -> 7 | AM17: Item Code | AN17: RM-203 | AO17: =(_xlfn.XMATCH(AN17,Item[Item Code],0,))+1 -> 10 | AY17: Item Code | AZ17: RM-208 | BA17: =(_xlfn.XMATCH(AZ17,Item[Item Code],0,))+1 -> 15 | BK17: Item Code | BL17: RM-213 | BM17: =(_xlfn.XMATCH(BL17,Item[Item Code],0,))+1 -> 20
C18: On Hand Inventory | D18: =HLOOKUP(C18,Item[[#All],[Item Code]:[Lead Time]],E$17,) -> 300 | O18: On Hand Inventory | P18: =HLOOKUP(O18,Item[[#All],[Item Code]:[Lead Time]],Q$17,) -> 110 | AA18: On Hand Inventory | AB18: =HLOOKUP(AA18,Item[[#All],[Item Code]:[Lead Time]],AC$17,) -> 85 | AM18: On Hand Inventory | AN18: =HLOOKUP(AM18,Item[[#All],[Item Code]:[Lead Time]],AO$17,) -> 650 | AY18: On Hand Inventory | AZ18: =HLOOKUP(AY18,Item[[#All],[Item Code]:[Lead Time]],BA$17,) -> 145 | BK18: On Hand Inventory | BL18: =HLOOKUP(BK18,Item[[#All],[Item Code]:[Lead Time]],BM$17,) -> 210
C19: Safety Stock | D19: =HLOOKUP(C19,Item[[#All],[Item Code]:[Lead Time]],E$17,) -> 100 | O19: Safety Stock | P19: =HLOOKUP(O19,Item[[#All],[Item Code]:[Lead Time]],Q$17,) -> 40 | AA19: Safety Stock | AB19: =HLOOKUP(AA19,Item[[#All],[Item Code]:[Lead Time]],AC$17,) -> 30 | AM19: Safety Stock | AN19: =HLOOKUP(AM19,Item[[#All],[Item Code]:[Lead Time]],AO$17,) -> 200 | AY19: Safety Stock | AZ19: =HLOOKUP(AY19,Item[[#All],[Item Code]:[Lead Time]],BA$17,) -> 50 | BK19: Safety Stock | BL19: =HLOOKUP(BK19,Item[[#All],[Item Code]:[Lead Time]],BM$17,) -> 80
C20: Lot Size | D20: =HLOOKUP(C20,Item[[#All],[Item Code]:[Lead Time]],E$17,) -> 0 | O20: Lot Size | P20: =HLOOKUP(O20,Item[[#All],[Item Code]:[Lead Time]],Q$17,) -> 200 | AA20: Lot Size | AB20: =HLOOKUP(AA20,Item[[#All],[Item Code]:[Lead Time]],AC$17,) -> 150 | AM20: Lot Size | AN20: =HLOOKUP(AM20,Item[[#All],[Item Code]:[Lead Time]],AO$17,) -> 500 | AY20: Lot Size | AZ20: =HLOOKUP(AY20,Item[[#All],[Item Code]:[Lead Time]],BA$17,) -> 150 | BK20: Lot Size | BL20: =HLOOKUP(BK20,Item[[#All],[Item Code]:[Lead Time]],BM$17,) -> 200
C21: Lead Time | D21: =HLOOKUP(C21,Item[[#All],[Item Code]:[Lead Time]],E$17,) -> 1 | O21: Lead Time | P21: =HLOOKUP(O21,Item[[#All],[Item Code]:[Lead Time]],Q$17,) -> 1 | AA21: Lead Time | AB21: =HLOOKUP(AA21,Item[[#All],[Item Code]:[Lead Time]],AC$17,) -> 1 | AM21: Lead Time | AN21: =HLOOKUP(AM21,Item[[#All],[Item Code]:[Lead Time]],AO$17,) -> 2 | AY21: Lead Time | AZ21: =HLOOKUP(AY21,Item[[#All],[Item Code]:[Lead Time]],BA$17,) -> 2 | BK21: Lead Time | BL21: =HLOOKUP(BK21,Item[[#All],[Item Code]:[Lead Time]],BM$17,) -> 2
C22: Jumlah | D22: =_xlfn.XLOOKUP(D17,BOM[Component Item],BOM[Quantity Per Assembly]) -> 2 | O22: Jumlah | P22: =_xlfn.XLOOKUP(P17,BOM[Component Item],BOM[Quantity Per Assembly]) -> 1 | AA22: Jumlah | AB22: =_xlfn.XLOOKUP(AB17,BOM[Component Item],BOM[Quantity Per Assembly]) -> 1 | AM22: Jumlah | AN22: =_xlfn.XLOOKUP(AN17,BOM[Component Item],BOM[Quantity Per Assembly]) -> 3 | AY22: Jumlah | AZ22: =_xlfn.XLOOKUP(AZ17,BOM[Component Item],BOM[Quantity Per Assembly]) -> 2 | BK22: Jumlah | BL22: =_xlfn.XLOOKUP(BL17,BOM[Component Item],BOM[Quantity Per Assembly]) -> 2
C23: Minggu | D23: {=_xlfn.SEQUENCE(,9,0)} -> 0 | E23: 1 | F23: 2 | G23: 3 | H23: 4 | I23: 5 | J23: 6 | K23: 7 | L23: 8 | O23: Minggu | P23: {=_xlfn.SEQUENCE(,9,0)} -> 0 | Q23: 1 | R23: 2 | S23: 3 | T23: 4 | U23: 5 | V23: 6 | W23: 7 | X23: 8 | AA23: Minggu | AB23: {=_xlfn.SEQUENCE(,9,0)} -> 0 | AC23: 1 | AD23: 2 | AE23: 3 | AF23: 4 | AG23: 5 | AH23: 6 | AI23: 7 | AJ23: 8 | AM23: Minggu | AN23: {=_xlfn.SEQUENCE(,9,0)} -> 0 | AO23: 1 | AP23: 2 | AQ23: 3 | AR23: 4 | AS23: 5 | AT23: 6 | AU23: 7 | AV23: 8 | AY23: Minggu | AZ23: {=_xlfn.SEQUENCE(,9,0)} -> 0 | BA23: 1 | BB23: 2 | BC23: 3 | BD23: 4 | BE23: 5 | BF23: 6 | BG23: 7 | BH23: 8 | BK23: Minggu | BL23: {=_xlfn.SEQUENCE(,9,0)} -> 0 | BM23: 1 | BN23: 2 | BO23: 3 | BP23: 4 | BQ23: 5 | BR23: 6 | BS23: 7 | BT23: 8
C24: Gross Requirement | E24: {=$E$14:$L$14} -> 0 | F24: 100 | G24: 100 | H24: 100 | I24: 100 | J24: 200 | K24: 0 | L24: 0 | O24: Gross Requirement | Q24: {=($Q$14:$X$14)*P22} -> 0 | R24: 100 | S24: 100 | T24: 100 | U24: 100 | V24: 200 | W24: 100 | X24: 0 | AA24: Gross Requirement | AC24: {=$AC$14:$AJ$14*AB22} -> 0 | AD24: 80 | AE24: 80 | AF24: 160 | AG24: 80 | AH24: 160 | AI24: 80 | AJ24: 0 | AM24: Gross Requirement | AO24: {=$AO$14:$AV$14*AN22} -> 0 | AP24: 240 | AQ24: 480 | AR24: 0 | AS24: 480 | AT24: 0 | AU24: 0 | AV24: 0 | AY24: Gross Requirement | BA24: {=$BA$14:$BH$14*AZ22} -> 120 | BB24: 120 | BC24: 240 | BD24: 120 | BE24: 480 | BF24: 120 | BG24: 0 | BH24: 0 | BK24: Gross Requirement | BM24: {=$BM$14:$BR$14*BL22} -> 120 | BN24: 120 | BO24: 240 | BP24: 240 | BQ24: 240 | BR24: 240
C25: Scheduled Receipt | F25: 200 | O25: Scheduled Receipt | AA25: Scheduled Receipt | AH25: 150 | AM25: Scheduled Receipt | AP25: 500 | AY25: Scheduled Receipt | BE25: 150 | BK25: Scheduled Receipt | BQ25: 200
C26: On Hand | D26: =D18 -> 300 | E26: =D26+E28+E25+-E24 -> 300 | F26: =E26+F28+F25+-F24 -> 400 | G26: =F26+G28+G25+-G24 -> 300 | H26: =G26+H28+H25+-H24 -> 200 | I26: =H26+I28+I25+-I24 -> 100 | J26: =I26+J28+J25+-J24 -> 100 | K26: =J26+K28+K25+-K24 -> 100 | L26: =K26+L28+L25+-L24 -> 100 | O26: On Hand | P26: =P18 -> 110 | Q26: =P26+Q28+Q25+-Q24 -> 110 | R26: =Q26+R28+R25+-R24 -> 210 | S26: =R26+S28+S25+-S24 -> 110 | T26: =S26+T28+T25+-T24 -> 210 | U26: =T26+U28+U25+-U24 -> 110 | V26: =U26+V28+V25+-V24 -> 110 | W26: =V26+W28+W25+-W24 -> 210 | X26: =W26+X28+X25+-X24 -> 210 | AA26: On Hand | AB26: =AB18 -> 85 | AC26: =AB26+AC28+AC25+-AC24 -> 85 | AD26: =AC26+AD28+AD25+-AD24 -> 155 | AE26: =AD26+AE28+AE25+-AE24 -> 75 | AF26: =AE26+AF28+AF25+-AF24 -> 65 | AG26: =AF26+AG28+AG25+-AG24 -> 135 | AH26: =AG26+AH28+AH25+-AH24 -> 125 | AI26: =AH26+AI28+AI25+-AI24 -> 45 | AJ26: =AI26+AJ28+AJ25+-AJ24 -> 45 | AM26: On Hand | AN26: =AN18 -> 650 | AO26: =AN26+AO28+AO25+-AO24 -> 650 | AP26: =AO26+AP28+AP25+-AP24 -> 910 | AQ26: =AP26+AQ28+AQ25+-AQ24 -> 430 | AR26: =AQ26+AR28+AR25+-AR24 -> 430 | AS26: =AR26+AS28+AS25+-AS24 -> 450 | AT26: =AS26+AT28+AT25+-AT24 -> 450 | AU26: =AT26+AU28+AU25+-AU24 -> 450 | AV26: =AU26+AV28+AV25+-AV24 -> 450 | AY26: On Hand | AZ26: =AZ18 -> 145 | BA26: =AZ26+BA28+BA25+-BA24 -> 25 | BB26: =BA26+BB28+BB25+-BB24 -> 55 | BC26: =BB26+BC28+BC25+-BC24 -> 115 | BD26: =BC26+BD28+BD25+-BD24 -> 145 | BE26: =BD26+BE28+BE25+-BE24 -> 115 | BF26: =BE26+BF28+BF25+-BF24 -> 145 | BG26: =BF26+BG28+BG25+-BG24 -> 145 | BH26: =BG26+BH28+BH25+-BH24 -> 145 | BK26: On Hand | BL26: =BL18 -> 210 | BM26: =BL26+BM28+BM25+-BM24 -> 90 | BN26: =BM26+BN28+BN25+-BN24 -> 170 | BO26: =BN26+BO28+BO25+-BO24 -> 130 | BP26: =BO26+BP28+BP25+-BP24 -> 90 | BQ26: =BP26+BQ28+BQ25+-BQ24 -> 250 | BR26: =BQ26+BR28+BR25+-BR24 -> 210 | BS26: =BR26+BS28+BS25+-BS24 -> 210 | BT26: =BS26+BT28+BT25+-BT24 -> 210
C27: Net Requirement | E27: =IF(E24+$D$19-E25-D26<0, 0,E24+$D$19-E25-D26) -> 0 | F27: =IF(F24+$D$19-F25-E26<0, 0,F24+$D$19-F25-E26) -> 0 | G27: =IF(G24+$D$19-G25-F26<0, 0,G24+$D$19-G25-F26) -> 0 | H27: =IF(H24+$D$19-H25-G26<0, 0,H24+$D$19-H25-G26) -> 0 | I27: =IF(I24+$D$19-I25-H26<0, 0,I24+$D$19-I25-H26) -> 0 | J27: =IF(J24+$D$19-J25-I26<0, 0,J24+$D$19-J25-I26) -> 200 | K27: =IF(K24+$D$19-K25-J26<0, 0,K24+$D$19-K25-J26) -> 0 | L27: =IF(L24+$D$19-L25-K26<0, 0,L24+$D$19-L25-K26) -> 0 | O27: Net Requirement | Q27: =IF(Q24+$P$19-Q25-P26<0, 0,Q24+$P$19-Q25-P26) -> 0 | R27: =IF(R24+$P$19-R25-Q26<0, 0,R24+$P$19-R25-Q26) -> 30 | S27: =IF(S24+$P$19-S25-R26<0, 0,S24+$P$19-S25-R26) -> 0 | T27: =IF(T24+$P$19-T25-S26<0, 0,T24+$P$19-T25-S26) -> 30 | U27: =IF(U24+$P$19-U25-T26<0, 0,U24+$P$19-U25-T26) -> 0 | V27: =IF(V24+$P$19-V25-U26<0, 0,V24+$P$19-V25-U26) -> 130 | W27: =IF(W24+$P$19-W25-V26<0, 0,W24+$P$19-W25-V26) -> 30 | X27: =IF(X24+$P$19-X25-W26<0, 0,X24+$P$19-X25-W26) -> 0 | AA27: Net Requirement | AC27: =IF(AC24+$AB$19-AC25-AB26<0, 0,AC24+$AB$19-AC25-AB26) -> 0 | AD27: =IF(AD24+$AB$19-AD25-AC26<0, 0,AD24+$AB$19-AD25-AC26) -> 25 | AE27: =IF(AE24+$AB$19-AE25-AD26<0, 0,AE24+$AB$19-AE25-AD26) -> 0 | AF27: =IF(AF24+$AB$19-AF25-AE26<0, 0,AF24+$AB$19-AF25-AE26) -> 115 | AG27: =IF(AG24+$AB$19-AG25-AF26<0, 0,AG24+$AB$19-AG25-AF26) -> 45 | AH27: =IF(AH24+$AB$19-AH25-AG26<0, 0,AH24+$AB$19-AH25-AG26) -> 0 | AI27: =IF(AI24+$AB$19-AI25-AH26<0, 0,AI24+$AB$19-AI25-AH26) -> 0 | AJ27: =IF(AJ24+$AB$19-AJ25-AI26<0, 0,AJ24+$AB$19-AJ25-AI26) -> 0 | AM27: Net Requirement | AO27: =IF(AO24+$AN$19-AO25-AN26<0, 0,AO24+$AN$19-AO25-AN26) -> 0 | AP27: =IF(AP24+$AN$19-AP25-AO26<0, 0,AP24+$AN$19-AP25-AO26) -> 0 | AQ27: =IF(AQ24+$AN$19-AQ25-AP26<0, 0,AQ24+$AN$19-AQ25-AP26) -> 0 | AR27: =IF(AR24+$AN$19-AR25-AQ26<0, 0,AR24+$AN$19-AR25-AQ26) -> 0 | AS27: =IF(AS24+$AN$19-AS25-AR26<0, 0,AS24+$AN$19-AS25-AR26) -> 250 | AT27: =IF(AT24+$AN$19-AT25-AS26<0, 0,AT24+$AN$19-AT25-AS26) -> 0 | AU27: =IF(AU24+$AN$19-AU25-AT26<0, 0,AU24+$AN$19-AU25-AT26) -> 0 | AV27: =IF(AV24+$AN$19-AV25-AU26<0, 0,AV24+$AN$19-AV25-AU26) -> 0 | AY27: Net Requirement | BA27: =IF(BA24+$AZ$19-BA25-AZ26<0, 0,BA24+$AZ$19-BA25-AZ26) -> 25 | BB27: =IF(BB24+$AZ$19-BB25-BA26<0, 0,BB24+$AZ$19-BB25-BA26) -> 145 | BC27: =IF(BC24+$AZ$19-BC25-BB26<0, 0,BC24+$AZ$19-BC25-BB26) -> 235 | BD27: =IF(BD24+$AZ$19-BD25-BC26<0, 0,BD24+$AZ$19-BD25-BC26) -> 55 | BE27: =IF(BE24+$AZ$19-BE25-BD26<0, 0,BE24+$AZ$19-BE25-BD26) -> 235 | BF27: =IF(BF24+$AZ$19-BF25-BE26<0, 0,BF24+$AZ$19-BF25-BE26) -> 55 | BG27: =IF(BG24+$AZ$19-BG25-BF26<0, 0,BG24+$AZ$19-BG25-BF26) -> 0 | BH27: =IF(BH24+$AZ$19-BH25-BG26<0, 0,BH24+$AZ$19-BH25-BG26) -> 0 | BK27: Net Requirement | BM27: =IF(BM24+$BL$19-BM25-BL26<0, 0,BM24+$BL$19-BM25-BL26) -> 0 | BN27: =IF(BN24+$BL$19-BN25-BM26<0, 0,BN24+$BL$19-BN25-BM26) -> 110 | BO27: =IF(BO24+$BL$19-BO25-BN26<0, 0,BO24+$BL$19-BO25-BN26) -> 150 | BP27: =IF(BP24+$BL$19-BP25-BO26<0, 0,BP24+$BL$19-BP25-BO26) -> 190 | BQ27: =IF(BQ24+$BL$19-BQ25-BP26<0, 0,BQ24+$BL$19-BQ25-BP26) -> 30 | BR27: =IF(BR24+$BL$19-BR25-BQ26<0, 0,BR24+$BL$19-BR25-BQ26) -> 70 | BS27: =IF(BS24+$BL$19-BS25-BR26<0, 0,BS24+$BL$19-BS25-BR26) -> 0 | BT27: =IF(BT24+$BL$19-BT25-BS26<0, 0,BT24+$BL$19-BT25-BS26) -> 0
C28: Planned Production Order | E28: =D29 -> 0 | F28: =E29 -> 0 | G28: =F29 -> 0 | H28: =G29 -> 0 | I28: =H29 -> 0 | J28: =I29 -> 200 | K28: =J29 -> 0 | L28: =K29 -> 0 | O28: Planned Production Order | Q28: =P29 -> 0 | R28: =Q29 -> 200 | S28: =R29 -> 0 | T28: =S29 -> 200 | U28: =T29 -> 0 | V28: =U29 -> 200 | W28: =V29 -> 200 | X28: =W29 -> 0 | AA28: Planned Production Order | AC28: =AB29 -> 0 | AD28: =AC29 -> 150 | AE28: =AD29 -> 0 | AF28: =AE29 -> 150 | AG28: =AF29 -> 150 | AH28: =AG29 -> 0 | AI28: =AH29 -> 0 | AJ28: =AI29 -> 0 | AM28: Planned Production Order | AP28: =AN29 -> 0 | AQ28: =AO29 -> 0 | AR28: =AP29 -> 0 | AS28: =AQ29 -> 500 | AT28: =AR29 -> 0 | AU28: =AS29 -> 0 | AV28: =AT29 -> 0 | AY28: Planned Production Order | BB28: =AZ29 -> 150 | BC28: =BA29 -> 300 | BD28: =BB29 -> 150 | BE28: =BC29 -> 300 | BF28: =BD29 -> 150 | BG28: =BE29 -> 0 | BH28: =BF29 -> 0 | BK28: Planned Production Order | BN28: =BL29 -> 200 | BO28: =BM29 -> 200 | BP28: =BN29 -> 200 | BQ28: =BO29 -> 200 | BR28: =BP29 -> 200 | BS28: =BQ29 -> 0 | BT28: =BR29 -> 0
C29: Planned Production Release | I29: 200 | O29: Planned Production Release | Q29: 200 | S29: 200 | U29: 200 | V29: 200 | AA29: Planned Production Release | AC29: 150 | AE29: 150 | AF29: 150 | AM29: Planned Production Release | AQ29: 500 | AY29: Planned Production Release | AZ29: 150 | BA29: 300 | BB29: 150 | BC29: 300 | BD29: 150 | BK29: Planned Production Release | BL29: 200 | BM29: 200 | BN29: 200 | BO29: 200 | BP29: 200
C32: Item Code | D32: RM-202 | E32: =(_xlfn.XMATCH(D32,Item[Item Code],0,))+1 -> 9 | O32: Item Code | P32: RM-206 | Q32: =(_xlfn.XMATCH(P32,Item[Item Code],0,))+1 -> 13 | AA32: Item Code | AB32: RM-211 | AC32: =(_xlfn.XMATCH(AB32,Item[Item Code],0,))+1 -> 18 | AM32: Item Code | AN32: RM-204 | AO32: =(_xlfn.XMATCH(AN32,Item[Item Code],0,))+1 -> 11 | AY32: Item Code | AZ32: RM-209 | BA32: =(_xlfn.XMATCH(AZ32,Item[Item Code],0,))+1 -> 16 | BK32: Item Code | BL32: RM-214 | BM32: =(_xlfn.XMATCH(BL32,Item[Item Code],0,))+1 -> 21
C33: On Hand Inventory | D33: =HLOOKUP(C33,Item[[#All],[Item Code]:[Lead Time]],E$32,) -> 240 | O33: On Hand Inventory | P33: =HLOOKUP(O33,Item[[#All],[Item Code]:[Lead Time]],Q$32,) -> 260 | AA33: On Hand Inventory | AB33: =HLOOKUP(AA33,Item[[#All],[Item Code]:[Lead Time]],AC$32,) -> 190 | AM33: On Hand Inventory | AN33: =HLOOKUP(AM33,Item[[#All],[Item Code]:[Lead Time]],AO$32,) -> 900 | AY33: On Hand Inventory | AZ33: =HLOOKUP(AY33,Item[[#All],[Item Code]:[Lead Time]],BA$32,) -> 420 | BK33: On Hand Inventory | BL33: =HLOOKUP(BK33,Item[[#All],[Item Code]:[Lead Time]],BM$32,) -> 160
C34: Safety Stock | D34: =HLOOKUP(C34,Item[[#All],[Item Code]:[Lead Time]],E$32,) -> 80 | O34: Safety Stock | P34: =HLOOKUP(O34,Item[[#All],[Item Code]:[Lead Time]],Q$32,) -> 100 | AA34: Safety Stock | AB34: =HLOOKUP(AA34,Item[[#All],[Item Code]:[Lead Time]],AC$32,) -> 60 | AM34: Safety Stock | AN34: =HLOOKUP(AM34,Item[[#All],[Item Code]:[Lead Time]],AO$32,) -> 300 | AY34: Safety Stock | AZ34: =HLOOKUP(AY34,Item[[#All],[Item Code]:[Lead Time]],BA$32,) -> 150 | BK34: Safety Stock | BL34: =HLOOKUP(BK34,Item[[#All],[Item Code]:[Lead Time]],BM$32,) -> 50
C35: Lot Size | D35: =HLOOKUP(C35,Item[[#All],[Item Code]:[Lead Time]],E$32,) -> 0 | O35: Lot Size | P35: =HLOOKUP(O35,Item[[#All],[Item Code]:[Lead Time]],Q$32,) -> 0 | AA35: Lot Size | AB35: =HLOOKUP(AA35,Item[[#All],[Item Code]:[Lead Time]],AC$32,) -> 0 | AM35: Lot Size | AN35: =HLOOKUP(AM35,Item[[#All],[Item Code]:[Lead Time]],AO$32,) -> 1000 | AY35: Lot Size | AZ35: =HLOOKUP(AY35,Item[[#All],[Item Code]:[Lead Time]],BA$32,) -> 0 | BK35: Lot Size | BL35: =HLOOKUP(BK35,Item[[#All],[Item Code]:[Lead Time]],BM$32,) -> 0
C36: Lead Time | D36: =HLOOKUP(C36,Item[[#All],[Item Code]:[Lead Time]],E$32,) -> 1 | O36: Lead Time | P36: =HLOOKUP(O36,Item[[#All],[Item Code]:[Lead Time]],Q$32,) -> 1 | AA36: Lead Time | AB36: =HLOOKUP(AA36,Item[[#All],[Item Code]:[Lead Time]],AC$32,) -> 2 | AM36: Lead Time | AN36: =HLOOKUP(AM36,Item[[#All],[Item Code]:[Lead Time]],AO$32,) -> 1 | AY36: Lead Time | AZ36: =HLOOKUP(AY36,Item[[#All],[Item Code]:[Lead Time]],BA$32,) -> 1 | BK36: Lead Time | BL36: =HLOOKUP(BK36,Item[[#All],[Item Code]:[Lead Time]],BM$32,) -> 1
C37: Jumlah | D37: =_xlfn.XLOOKUP(D32,BOM[Component Item],BOM[Quantity Per Assembly]) -> 1 | O37: Jumlah | P37: =_xlfn.XLOOKUP(P32,BOM[Component Item],BOM[Quantity Per Assembly]) -> 4 | AA37: Jumlah | AB37: =_xlfn.XLOOKUP(AB32,BOM[Component Item],BOM[Quantity Per Assembly]) -> 2 | AM37: Jumlah | AN37: =_xlfn.XLOOKUP(AN32,BOM[Component Item],BOM[Quantity Per Assembly]) -> 2 | AY37: Jumlah | AZ37: =_xlfn.XLOOKUP(AZ32,BOM[Component Item],BOM[Quantity Per Assembly]) -> 1 | BK37: Jumlah | BL37: =_xlfn.XLOOKUP(BL32,BOM[Component Item],BOM[Quantity Per Assembly]) -> 3
C38: Minggu | D38: {=_xlfn.SEQUENCE(,9,0)} -> 0 | E38: 1 | F38: 2 | G38: 3 | H38: 4 | I38: 5 | J38: 6 | K38: 7 | L38: 8 | O38: Minggu | P38: {=_xlfn.SEQUENCE(,9,0)} -> 0 | Q38: 1 | R38: 2 | S38: 3 | T38: 4 | U38: 5 | V38: 6 | W38: 7 | X38: 8 | AA38: Minggu | AB38: {=_xlfn.SEQUENCE(,9,0)} -> 0 | AC38: 1 | AD38: 2 | AE38: 3 | AF38: 4 | AG38: 5 | AH38: 6 | AI38: 7 | AJ38: 8 | AM38: Minggu | AN38: {=_xlfn.SEQUENCE(,9,0)} -> 0 | AO38: 1 | AP38: 2 | AQ38: 3 | AR38: 4 | AS38: 5 | AT38: 6 | AU38: 7 | AV38: 8 | AY38: Minggu | AZ38: {=_xlfn.SEQUENCE(,9,0)} -> 0 | BA38: 1 | BB38: 2 | BC38: 3 | BD38: 4 | BE38: 5 | BF38: 6 | BG38: 7 | BH38: 8 | BK38: Minggu | BL38: {=_xlfn.SEQUENCE(,9,0)} -> 0 | BM38: 1 | BN38: 2 | BO38: 3 | BP38: 4 | BQ38: 5 | BR38: 6 | BS38: 7 | BT38: 8
C39: Gross Requirement | E39: =F13 -> 0 | F39: =G13 -> 100 | G39: =H13 -> 100 | H39: =I13 -> 100 | I39: =J13 -> 100 | J39: =K13 -> 200 | K39: =L13 -> 0 | L39: =M13 -> 0 | O39: Gross Requirement | Q39: {=($Q$14:$X$14)*P37} -> 0 | R39: 400 | S39: 400 | T39: 400 | U39: 400 | V39: 800 | W39: 400 | X39: 0 | AA39: Gross Requirement | AC39: {=$AC$14:$AJ$14*AB37} -> 0 | AD39: 160 | AE39: 160 | AF39: 320 | AG39: 160 | AH39: 320 | AI39: 160 | AJ39: 0 | AM39: Gross Requirement | AO39: {=$AO$14:$AV$14*AN37} -> 0 | AP39: 160 | AQ39: 320 | AR39: 0 | AS39: 320 | AT39: 0 | AU39: 0 | AV39: 0 | AY39: Gross Requirement | BA39: {=$BA$14:$BH$14*AZ37} -> 60 | BB39: 60 | BC39: 120 | BD39: 60 | BE39: 240 | BF39: 60 | BG39: 0 | BH39: 0 | BK39: Gross Requirement | BM39: {=$BM$14:$BR$14*BL37} -> 180 | BN39: 180 | BO39: 360 | BP39: 360 | BQ39: 360 | BR39: 360
C40: Scheduled Receipt | H40: 150 | O40: Scheduled Receipt | AA40: Scheduled Receipt | AM40: Scheduled Receipt | AQ40: 1000 | AY40: Scheduled Receipt | BK40: Scheduled Receipt
C41: On Hand | D41: =D33 -> 240 | E41: =D41+E43+E40+-E39 -> 240 | F41: =E41+F43+F40+-F39 -> 140 | G41: =F41+G43+G40+-G39 -> 80 | H41: =G41+H43+H40+-H39 -> 130 | I41: =H41+I43+I40+-I39 -> 80 | J41: =I41+J43+J40+-J39 -> 80 | K41: =J41+K43+K40+-K39 -> 80 | L41: =K41+L43+L40+-L39 -> 80 | O41: On Hand | P41: =P33 -> 260 | Q41: =P41+Q43+Q40+-Q39 -> 260 | R41: =Q41+R43+R40+-R39 -> 160 | S41: =R41+S43+S40+-S39 -> 160 | T41: =S41+T43+T40+-T39 -> 160 | U41: =T41+U43+U40+-U39 -> 160 | V41: =U41+V43+V40+-V39 -> 160 | W41: =V41+W43+W40+-W39 -> 160 | X41: =W41+X43+X40+-X39 -> 160 | AA41: On Hand | AB41: =AB33 -> 190 | AC41: =AB41+AC43+AC40+-AC39 -> 190 | AD41: =AC41+AD43+AD40+-AD39 -> 60 | AE41: =AD41+AE43+AE40+-AE39 -> 60 | AF41: =AE41+AF43+AF40+-AF39 -> 60 | AG41: =AF41+AG43+AG40+-AG39 -> 60 | AH41: =AG41+AH43+AH40+-AH39 -> 60 | AI41: =AH41+AI43+AI40+-AI39 -> 60 | AJ41: =AI41+AJ43+AJ40+-AJ39 -> 60 | AM41: On Hand | AN41: =AN33 -> 900 | AO41: =AN41+AO43+AO40+-AO39 -> 900 | AP41: =AO41+AP43+AP40+-AP39 -> 740 | AQ41: =AP41+AQ43+AQ40+-AQ39 -> 1420 | AR41: =AQ41+AR43+AR40+-AR39 -> 1420 | AS41: =AR41+AS43+AS40+-AS39 -> 1100 | AT41: =AS41+AT43+AT40+-AT39 -> 1100 | AU41: =AT41+AU43+AU40+-AU39 -> 1100 | AV41: =AU41+AV43+AV40+-AV39 -> 1100 | AY41: On Hand | AZ41: =AZ33 -> 420 | BA41: =AZ41+BA43+BA40+-BA39 -> 360 | BB41: =BA41+BB43+BB40+-BB39 -> 300 | BC41: =BB41+BC43+BC40+-BC39 -> 180 | BD41: =BC41+BD43+BD40+-BD39 -> 150 | BE41: =BD41+BE43+BE40+-BE39 -> 150 | BF41: =BE41+BF43+BF40+-BF39 -> 150 | BG41: =BF41+BG43+BG40+-BG39 -> 150 | BH41: =BG41+BH43+BH40+-BH39 -> 150 | BK41: On Hand | BL41: =BL33 -> 160 | BM41: =BL41+BM43+BM40+-BM39 -> 50 | BN41: =BM41+BN43+BN40+-BN39 -> 50 | BO41: =BN41+BO43+BO40+-BO39 -> 50 | BP41: =BO41+BP43+BP40+-BP39 -> 50 | BQ41: =BP41+BQ43+BQ40+-BQ39 -> 50 | BR41: =BQ41+BR43+BR40+-BR39 -> 50 | BS41: =BR41+BS43+BS40+-BS39 -> 50 | BT41: =BS41+BT43+BT40+-BT39 -> 50
C42: Net Requirement | E42: =IF(E39+$D$34-E40-D41<0, 0,E39+$D$34-E40-D41) -> 0 | F42: =IF(F39+$D$34-F40-E41<0, 0,F39+$D$34-F40-E41) -> 0 | G42: =IF(G39+$D$34-G40-F41<0, 0,G39+$D$34-G40-F41) -> 40 | H42: =IF(H39+$D$34-H40-G41<0, 0,H39+$D$34-H40-G41) -> 0 | I42: =IF(I39+$D$34-I40-H41<0, 0,I39+$D$34-I40-H41) -> 50 | J42: =IF(J39+$D$34-J40-I41<0, 0,J39+$D$34-J40-I41) -> 200 | K42: =IF(K39+$D$34-K40-J41<0, 0,K39+$D$34-K40-J41) -> 0 | L42: =IF(L39+$D$34-L40-K41<0, 0,L39+$D$34-L40-K41) -> 0 | O42: Net Requirement | Q42: =IF(Q39+$P$34-Q40-P41<0, 0,Q39+$P$34-Q40-P41) -> 0 | R42: =IF(R39+$P$34-R40-Q41<0, 0,R39+$P$34-R40-Q41) -> 240 | S42: =IF(S39+$P$34-S40-R41<0, 0,S39+$P$34-S40-R41) -> 340 | T42: =IF(T39+$P$34-T40-S41<0, 0,T39+$P$34-T40-S41) -> 340 | U42: =IF(U39+$P$34-U40-T41<0, 0,U39+$P$34-U40-T41) -> 340 | V42: =IF(V39+$P$34-V40-U41<0, 0,V39+$P$34-V40-U41) -> 740 | W42: =IF(W39+$P$34-W40-V41<0, 0,W39+$P$34-W40-V41) -> 340 | X42: =IF(X39+$P$34-X40-W41<0, 0,X39+$P$34-X40-W41) -> 0 | AA42: Net Requirement | AC42: =IF(AC39+$AB$34-AC40-AB41<0, 0,AC39+$AB$34-AC40-AB41) -> 0 | AD42: =IF(AD39+$AB$34-AD40-AC41<0, 0,AD39+$AB$34-AD40-AC41) -> 30 | AE42: =IF(AE39+$AB$34-AE40-AD41<0, 0,AE39+$AB$34-AE40-AD41) -> 160 | AF42: =IF(AF39+$AB$34-AF40-AE41<0, 0,AF39+$AB$34-AF40-AE41) -> 320 | AG42: =IF(AG39+$AB$34-AG40-AF41<0, 0,AG39+$AB$34-AG40-AF41) -> 160 | AH42: =IF(AH39+$AB$34-AH40-AG41<0, 0,AH39+$AB$34-AH40-AG41) -> 320 | AI42: =IF(AI39+$AB$34-AI40-AH41<0, 0,AI39+$AB$34-AI40-AH41) -> 160 | AJ42: =IF(AJ39+$AB$34-AJ40-AI41<0, 0,AJ39+$AB$34-AJ40-AI41) -> 0 | AM42: Net Requirement | AO42: =IF(AO39+$AN$19-AO40-AN41<0, 0,AO39+$AN$19-AO40-AN41) -> 0 | AP42: =IF(AP39+$AN$19-AP40-AO41<0, 0,AP39+$AN$19-AP40-AO41) -> 0 | AQ42: =IF(AQ39+$AN$19-AQ40-AP41<0, 0,AQ39+$AN$19-AQ40-AP41) -> 0 | AR42: =IF(AR39+$AN$19-AR40-AQ41<0, 0,AR39+$AN$19-AR40-AQ41) -> 0 | AS42: =IF(AS39+$AN$19-AS40-AR41<0, 0,AS39+$AN$19-AS40-AR41) -> 0 | AT42: =IF(AT39+$AN$19-AT40-AS41<0, 0,AT39+$AN$19-AT40-AS41) -> 0 | AU42: =IF(AU39+$AN$19-AU40-AT41<0, 0,AU39+$AN$19-AU40-AT41) -> 0 | AV42: =IF(AV39+$AN$19-AV40-AU41<0, 0,AV39+$AN$19-AV40-AU41) -> 0 | AY42: Net Requirement | BA42: =IF(BA39+$AZ$34-BA40-AZ41<0, 0,BA39+$AZ$34-BA40-AZ41) -> 0 | BB42: =IF(BB39+$AZ$34-BB40-BA41<0, 0,BB39+$AZ$34-BB40-BA41) -> 0 | BC42: =IF(BC39+$AZ$34-BC40-BB41<0, 0,BC39+$AZ$34-BC40-BB41) -> 0 | BD42: =IF(BD39+$AZ$34-BD40-BC41<0, 0,BD39+$AZ$34-BD40-BC41) -> 30 | BE42: =IF(BE39+$AZ$34-BE40-BD41<0, 0,BE39+$AZ$34-BE40-BD41) -> 240 | BF42: =IF(BF39+$AZ$34-BF40-BE41<0, 0,BF39+$AZ$34-BF40-BE41) -> 60 | BG42: =IF(BG39+$AZ$34-BG40-BF41<0, 0,BG39+$AZ$34-BG40-BF41) -> 0 | BH42: =IF(BH39+$AZ$34-BH40-BG41<0, 0,BH39+$AZ$34-BH40-BG41) -> 0 | BK42: Net Requirement | BM42: =IF(BM39+$BL$34-BM40-BL41<0, 0,BM39+$BL$34-BM40-BL41) -> 70 | BN42: =IF(BN39+$BL$34-BN40-BM41<0, 0,BN39+$BL$34-BN40-BM41) -> 180 | BO42: =IF(BO39+$BL$34-BO40-BN41<0, 0,BO39+$BL$34-BO40-BN41) -> 360 | BP42: =IF(BP39+$BL$34-BP40-BO41<0, 0,BP39+$BL$34-BP40-BO41) -> 360 | BQ42: =IF(BQ39+$BL$34-BQ40-BP41<0, 0,BQ39+$BL$34-BQ40-BP41) -> 360 | BR42: =IF(BR39+$BL$34-BR40-BQ41<0, 0,BR39+$BL$34-BR40-BQ41) -> 360 | BS42: =IF(BS39+$BL$34-BS40-BR41<0, 0,BS39+$BL$34-BS40-BR41) -> 0 | BT42: =IF(BT39+$BL$34-BT40-BS41<0, 0,BT39+$BL$34-BT40-BS41) -> 0
C43: Planned Production Order | E43: =D44 -> 0 | F43: =E44 -> 0 | G43: =F44 -> 40 | H43: =G44 -> 0 | I43: =H44 -> 50 | J43: =I44 -> 200 | K43: =J44 -> 0 | L43: =K44 -> 0 | O43: Planned Production Order | Q43: =P44 -> 0 | R43: =Q44 -> 300 | S43: =R44 -> 400 | T43: =S44 -> 400 | U43: =T44 -> 400 | V43: =U44 -> 800 | W43: =V44 -> 400 | X43: =W44 -> 0 | AA43: Planned Production Order | AC43: 0 | AD43: =AB44 -> 30 | AE43: =AC44 -> 160 | AF43: =AD44 -> 320 | AG43: =AE44 -> 160 | AH43: =AF44 -> 320 | AI43: =AG44 -> 160 | AJ43: =AH44 -> 0 | AM43: Planned Production Order | AO43: =AN44 -> 0 | AP43: =AO44 -> 0 | AQ43: =AP44 -> 0 | AR43: =AQ44 -> 0 | AS43: =AR44 -> 0 | AT43: =AS44 -> 0 | AU43: =AT44 -> 0 | AV43: =AU44 -> 0 | AY43: Planned Production Order | BA43: =AZ44 -> 0 | BB43: =BA44 -> 0 | BC43: =BB44 -> 0 | BD43: =BC44 -> 30 | BE43: =BD44 -> 240 | BF43: =BE44 -> 60 | BG43: =BF44 -> 0 | BH43: =BG44 -> 0 | BK43: Planned Production Order | BM43: =BL44 -> 70 | BN43: =BM44 -> 180 | BO43: =BN44 -> 360 | BP43: =BO44 -> 360 | BQ43: =BP44 -> 360 | BR43: =BQ44 -> 360 | BS43: =BR44 -> 0 | BT43: =BS44 -> 0
C44: Planned Production Release | F44: 40 | H44: 50 | I44: 200 | O44: Planned Production Release | Q44: 300 | R44: 400 | S44: 400 | T44: 400 | U44: 800 | V44: 400 | AA44: Planned Production Release | AB44: 30 | AC44: 160 | AD44: 320 | AE44: 160 | AF44: 320 | AG44: 160 | AM44: Planned Production Release | AY44: Planned Production Release | BC44: 30 | BD44: 240 | BE44: 60 | BK44: Planned Production Release | BL44: 70 | BM44: 180 | BN44: 360 | BO44: 360 | BP44: 360 | BQ44: 360
...

Sheet Sheet1
A1: ` | B1: Type | C1: Level | D1: Minggu 0 | E1: Order Minggu 1 | F1: Order Minggu 2 | G1: Order Minggu 3 | H1: Order Minggu 4 | I1: Order Minggu 5 | J1: Order Minggu 6 | K1: Order Minggu 7 | L1: Order Minggu 8
A2: FG-100 | B2: =_xlfn.XLOOKUP(A2,'ITEM MASTER'!$A:$A,'ITEM MASTER'!$C:$C,,0) -> Finished Goods | C2: 0 | D2: {=MRP!D14:L14} -> 100 | E2: 0 | F2: 100 | G2: 100 | H2: 100 | I2: 100 | J2: 200 | K2: 0 | L2: 0 | Q2: {=Item[Item Code]} -> FG-100
A3: RM-201 | B3: =_xlfn.XLOOKUP(A3,'ITEM MASTER'!$A:$A,'ITEM MASTER'!$C:$C,,0) -> Raw Material | C3: 1 | D3: {=MRP!D29:L29} -> 0 | E3: 0 | F3: 0 | G3: 0 | H3: 0 | I3: 200 | J3: 0 | K3: 0 | L3: 0 | Q3: FG-200
A4: RM-202 | B4: =_xlfn.XLOOKUP(A4,'ITEM MASTER'!$A:$A,'ITEM MASTER'!$C:$C,,0) -> Raw Material | C4: 1 | D4: {=MRP!D44:L44} -> 0 | E4: 0 | F4: 40 | G4: 0 | H4: 50 | I4: 200 | J4: 0 | K4: 0 | L4: 0 | Q4: FG-300
A5: SA-110 | B5: =_xlfn.XLOOKUP(A5,'ITEM MASTER'!$A:$A,'ITEM MASTER'!$C:$C,,0) -> Sub Assembly | C5: 1 | D5: {=MRP!D59:L59} -> 0 | E5: 0 | F5: 80 | G5: 160 | H5: 0 | I5: 160 | J5: 0 | K5: 0 | L5: 0 | Q5: PK-301
A6: PK-301 | B6: =_xlfn.XLOOKUP(A6,'ITEM MASTER'!$A:$A,'ITEM MASTER'!$C:$C,,0) -> Packaging | C6: 1 | D6: {=MRP!D74:L74} -> 0 | E6: 0 | F6: 200 | G6: 0 | H6: 200 | I6: 200 | J6: 0 | K6: 0 | L6: 0 | Q6: PK-302
A7: RM-203 | B7: =_xlfn.XLOOKUP(A7,'ITEM MASTER'!$A:$A,'ITEM MASTER'!$C:$C,,0) -> Raw Material | C7: 2 | D7: {=MRP!AN29:AV29} -> 0 | E7: 0 | F7: 0 | G7: 500 | H7: 0 | I7: 0 | J7: 0 | K7: 0 | L7: 0 | Q7: PK-303
A8: RM-204 | B8: =_xlfn.XLOOKUP(A8,'ITEM MASTER'!$A:$A,'ITEM MASTER'!$C:$C,,0) -> Raw Material | C8: 2 | D8: {=MRP!AN44:AV44} -> 0 | E8: 0 | F8: 0 | G8: 0 | H8: 0 | I8: 0 | J8: 0 | K8: 0 | L8: 0 | Q8: RM-201
A9: RM-205 | B9: =_xlfn.XLOOKUP(A9,'ITEM MASTER'!$A:$A,'ITEM MASTER'!$C:$C,,0) -> Raw Material | C9: 2 | D9: {=MRP!AN59:AV59} -> 0 | E9: 120 | F9: 0 | G9: 0 | H9: 0 | I9: 0 | J9: 0 | K9: 0 | L9: 0 | Q9: RM-202
A10: FG-200 | B10: =_xlfn.XLOOKUP(A10,'ITEM MASTER'!$A:$A,'ITEM MASTER'!$C:$C,,0) -> Finished Goods | C10: 0 | D10: {=MRP!P14:X14} -> 100 | E10: 0 | F10: 100 | G10: 100 | H10: 100 | I10: 100 | J10: 200 | K10: 100 | L10: 0 | Q10: RM-203
A11: PK-302 | B11: =_xlfn.XLOOKUP(A11,'ITEM MASTER'!$A:$A,'ITEM MASTER'!$C:$C,,0) -> Packaging | C11: 1 | D11: {=MRP!P29:X29} -> 0 | E11: 200 | F11: 0 | G11: 200 | H11: 0 | I11: 200 | J11: 200 | K11: 0 | L11: 0 | Q11: RM-204
A12: RM-206 | B12: =_xlfn.XLOOKUP(A12,'ITEM MASTER'!$A:$A,'ITEM MASTER'!$C:$C,,0) -> Raw Material | C12: 1 | D12: {=MRP!P44:X44} -> 0 | E12: 300 | F12: 400 | G12: 400 | H12: 400 | I12: 800 | J12: 400 | K12: 0 | L12: 0 | Q12: RM-205
A13: RM-207 | B13: =_xlfn.XLOOKUP(A13,'ITEM MASTER'!$A:$A,'ITEM MASTER'!$C:$C,,0) -> Raw Material | C13: 1 | D13: {=MRP!P59:X59} -> 0 | E13: 200 | F13: 200 | G13: 0 | H13: 200 | I13: 400 | J13: 200 | K13: 0 | L13: 0 | Q13: RM-206
A14: SA-210 | B14: =_xlfn.XLOOKUP(A14,'ITEM MASTER'!$A:$A,'ITEM MASTER'!$C:$C,,0) -> Sub Assembly | C14: 1 | D14: {=MRP!P74:X74} -> 0 | E14: 60 | F14: 60 | G14: 120 | H14: 60 | I14: 240 | J14: 60 | K14: 0 | L14: 0 | Q14: RM-207
A15: RM-208 | B15: =_xlfn.XLOOKUP(A15,'ITEM MASTER'!$A:$A,'ITEM MASTER'!$C:$C,,0) -> Raw Material | C15: 2 | D15: {=MRP!AZ29:BH29} -> 150 | E15: 300 | F15: 150 | G15: 300 | H15: 150 | I15: 0 | J15: 0 | K15: 0 | L15: 0 | Q15: RM-208
A16: RM-209 | B16: =_xlfn.XLOOKUP(A16,'ITEM MASTER'!$A:$A,'ITEM MASTER'!$C:$C,,0) -> Raw Material | C16: 2 | D16: {=MRP!AZ44:BH44} -> 0 | E16: 0 | F16: 0 | G16: 30 | H16: 240 | I16: 60 | J16: 0 | K16: 0 | L16: 0 | Q16: RM-209
A17: RM-210 | B17: =_xlfn.XLOOKUP(A17,'ITEM MASTER'!$A:$A,'ITEM MASTER'!$C:$C,,0) -> Raw Material | C17: 2 | D17: {=MRP!AZ59:BH59} -> 0 | E17: 300 | F17: 300 | G17: 300 | H17: 600 | I17: 300 | J17: 0 | K17: 0 | L17: 0 | Q17: RM-210
A18: FG-300 | B18: =_xlfn.XLOOKUP(A18,'ITEM MASTER'!$A:$A,'ITEM MASTER'!$C:$C,,0) -> Finished Goods | C18: 0 | D18: {=MRP!AB14:AJ14} -> 0 | E18: 0 | F18: 80 | G18: 80 | H18: 160 | I18: 80 | J18: 160 | K18: 80 | L18: 0 | Q18: RM-211
A19: PK-303 | B19: =_xlfn.XLOOKUP(A19,'ITEM MASTER'!$A:$A,'ITEM MASTER'!$C:$C,,0) -> Packaging | C19: 1 | D19: {=MRP!AB29:AJ29} -> 0 | E19: 150 | F19: 0 | G19: 150 | H19: 150 | I19: 0 | J19: 0 | K19: 0 | L19: 0 | Q19: RM-212
A20: RM-211 | B20: =_xlfn.XLOOKUP(A20,'ITEM MASTER'!$A:$A,'ITEM MASTER'!$C:$C,,0) -> Raw Material | C20: 1 | D20: {=MRP!AB44:AJ44} -> 30 | E20: 160 | F20: 320 | G20: 160 | H20: 320 | I20: 160 | J20: 0 | K20: 0 | L20: 0 | Q20: RM-213
A21: RM-212 | B21: =_xlfn.XLOOKUP(A21,'ITEM MASTER'!$A:$A,'ITEM MASTER'!$C:$C,,0) -> Raw Material | C21: 1 | D21: {=MRP!AB59:AJ59} -> 150 | E21: 150 | F21: 150 | G21: 150 | H21: 300 | I21: 150 | J21: 0 | K21: 0 | L21: 0 | Q21: RM-214
A22: SA-310 | B22: =_xlfn.XLOOKUP(A22,'ITEM MASTER'!$A:$A,'ITEM MASTER'!$C:$C,,0) -> Sub Assembly | C22: 1 | D22: {=MRP!BL14:BT14} -> 0 | E22: 60 | F22: 60 | G22: 120 | H22: 120 | I22: 120 | J22: 120 | K22: 0 | L22: 0 | Q22: RM-215
A23: RM-213 | B23: =_xlfn.XLOOKUP(A23,'ITEM MASTER'!$A:$A,'ITEM MASTER'!$C:$C,,0) -> Raw Material | C23: 2 | D23: {=MRP!BL29:BT29} -> 200 | E23: 200 | F23: 200 | G23: 200 | H23: 200 | I23: 0 | J23: 0 | K23: 0 | L23: 0 | Q23: SA-110
A24: RM-214 | B24: =_xlfn.XLOOKUP(A24,'ITEM MASTER'!$A:$A,'ITEM MASTER'!$C:$C,,0) -> Raw Material | C24: 2 | D24: {=MRP!BL44:BT44} -> 70 | E24: 180 | F24: 360 | G24: 360 | H24: 360 | I24: 360 | J24: 0 | K24: 0 | L24: 0 | Q24: SA-210
A25: RM-215 | B25: =_xlfn.XLOOKUP(A25,'ITEM MASTER'!$A:$A,'ITEM MASTER'!$C:$C,,0) -> Raw Material | C25: 2 | D25: {=MRP!BL59:BT59} -> 100 | E25: 100 | F25: 200 | G25: 100 | H25: 100 | I25: 0 | J25: 0 | K25: 0 | L25: 0 | Q25: SA-310

Sheet SCHEDULE RECEIPT
A1: Item Code | B1: Week | C1: Scheduled Receipt
A2: FG-100 | B2: Week 1 | C2: 0
A3: FG-100 | B3: Week 2 | C3: 100
A4: FG-100 | B4: Week 3 | C4: 0
A5: FG-100 | B5: Week 4 | C5: 0
A6: FG-100 | B6: Week 5 | C6: 100
A7: FG-100 | B7: Week 6 | C7: 0
A8: FG-100 | B8: Week 7 | C8: 0
A9: FG-100 | B9: Week 8 | C9: 100
A10: FG-200 | B10: Week 2 | C10: 100
A11: FG-300 | B11: Week 2 | C11: 80
A12: PK-303 | B12: W6 | C12: 150
A13: RM-201 | B13: Week 1 | C13: 0
... A31: SA-310 | B31: Week 3 | C31: 60
